[2021-04-11 00:54:01,238][Thread-7:4876][task_id:django.request][log.py:230][ERROR][Internal Server Error: /WebMail/showconfig/]
Traceback (most recent call last):
  File "D:\Anaconda3\envs\mail\lib\site-packages\django\core\handlers\exception.py", line 47, in inner
    response = get_response(request)
  File "D:\Anaconda3\envs\mail\lib\site-packages\django\core\handlers\base.py", line 181, in _get_response
    response = wrapped_callback(request, *callback_args, **callback_kwargs)
  File "D:\_2021Spring\计网\课设\DjangoMail\DjangoMail\WebMail\views.py", line 107, in ShowConfig
    configJson = settings.mailSystemServer.ConfigShow()
  File "D:\Anaconda3\envs\mail\lib\site-packages\django\conf\__init__.py", line 83, in __getattr__
    val = getattr(self._wrapped, name)
AttributeError: 'Settings' object has no attribute 'mailSystemServer'
[2021-04-11 01:05:26,551][Thread-7:13324][task_id:django.request][log.py:230][ERROR][Internal Server Error: /WebMail/showconfig/]
Traceback (most recent call last):
  File "D:\Anaconda3\envs\mail\lib\site-packages\django\core\handlers\exception.py", line 47, in inner
    response = get_response(request)
  File "D:\Anaconda3\envs\mail\lib\site-packages\django\core\handlers\base.py", line 181, in _get_response
    response = wrapped_callback(request, *callback_args, **callback_kwargs)
  File "D:\_2021Spring\计网\课设\DjangoMail\DjangoMail\WebMail\views.py", line 108, in ShowConfig
    configJson = settings.mailSystemServer.ConfigShow()
  File "D:\Anaconda3\envs\mail\lib\site-packages\django\conf\__init__.py", line 83, in __getattr__
    val = getattr(self._wrapped, name)
AttributeError: 'Settings' object has no attribute 'mailSystemServer'
[2021-04-11 01:07:07,197][Thread-7:21728][task_id:django.request][log.py:230][ERROR][Internal Server Error: /WebMail/showconfig/]
Traceback (most recent call last):
  File "D:\Anaconda3\envs\mail\lib\site-packages\django\core\handlers\exception.py", line 47, in inner
    response = get_response(request)
  File "D:\Anaconda3\envs\mail\lib\site-packages\django\core\handlers\base.py", line 181, in _get_response
    response = wrapped_callback(request, *callback_args, **callback_kwargs)
  File "D:\_2021Spring\计网\课设\DjangoMail\DjangoMail\WebMail\views.py", line 113, in ShowConfig
    configJson = settings.mailSystemServer.ConfigShow()
  File "D:\Anaconda3\envs\mail\lib\site-packages\django\conf\__init__.py", line 83, in __getattr__
    val = getattr(self._wrapped, name)
AttributeError: 'Settings' object has no attribute 'mailSystemServer'
[2021-04-11 01:15:45,005][Thread-7:2032][task_id:django.request][log.py:230][ERROR][Internal Server Error: /WebMail/resetconfig/]
Traceback (most recent call last):
  File "D:\Anaconda3\envs\mail\lib\site-packages\django\core\handlers\exception.py", line 47, in inner
    response = get_response(request)
  File "D:\Anaconda3\envs\mail\lib\site-packages\django\core\handlers\base.py", line 181, in _get_response
    response = wrapped_callback(request, *callback_args, **callback_kwargs)
  File "D:\_2021Spring\计网\课设\DjangoMail\DjangoMail\WebMail\views.py", line 107, in ShowConfig
    if not Check["result"]:
TypeError: 'function' object is not subscriptable
[2021-04-11 01:16:12,286][Thread-7:26300][task_id:django.request][log.py:230][ERROR][Internal Server Error: /WebMail/resetconfig/]
Traceback (most recent call last):
  File "D:\Anaconda3\envs\mail\lib\site-packages\django\core\handlers\exception.py", line 47, in inner
    response = get_response(request)
  File "D:\Anaconda3\envs\mail\lib\site-packages\django\core\handlers\base.py", line 181, in _get_response
    response = wrapped_callback(request, *callback_args, **callback_kwargs)
  File "D:\_2021Spring\计网\课设\DjangoMail\DjangoMail\WebMail\views.py", line 158, in ResetConfig
    "data": json.dumps(settings.mailSystemServer.ConfigDefault()),
  File "D:\Anaconda3\envs\mail\lib\site-packages\django\conf\__init__.py", line 83, in __getattr__
    val = getattr(self._wrapped, name)
AttributeError: 'Settings' object has no attribute 'mailSystemServer'
[2021-04-11 01:16:26,775][Thread-7:26300][task_id:django.request][log.py:230][ERROR][Internal Server Error: /WebMail/resetconfig/]
Traceback (most recent call last):
  File "D:\Anaconda3\envs\mail\lib\site-packages\django\core\handlers\exception.py", line 47, in inner
    response = get_response(request)
  File "D:\Anaconda3\envs\mail\lib\site-packages\django\core\handlers\base.py", line 181, in _get_response
    response = wrapped_callback(request, *callback_args, **callback_kwargs)
  File "D:\_2021Spring\计网\课设\DjangoMail\DjangoMail\WebMail\views.py", line 158, in ResetConfig
    "data": json.dumps(settings.mailSystemServer.ConfigDefault()),
  File "D:\Anaconda3\envs\mail\lib\site-packages\django\conf\__init__.py", line 83, in __getattr__
    val = getattr(self._wrapped, name)
AttributeError: 'Settings' object has no attribute 'mailSystemServer'
[2021-05-16 15:00:05,828][Thread-3:20584][task_id:django.request][log.py:230][ERROR][Internal Server Error: /webmail/listunreadedmails/]
Traceback (most recent call last):
  File "D:\Anaconda3\envs\mail\lib\site-packages\django\core\handlers\exception.py", line 47, in inner
    response = get_response(request)
  File "D:\Anaconda3\envs\mail\lib\site-packages\django\core\handlers\base.py", line 181, in _get_response
    response = wrapped_callback(request, *callback_args, **callback_kwargs)
  File "D:\_2021Spring\计网\课设\DjangoMail\DjangoMail\WebMail\views.py", line 613, in GetReadMailsbyId
    mailNo = int(mailNo)
TypeError: int() argument must be a string, a bytes-like object or a number, not 'NoneType'
[2021-05-16 21:00:37,920][Thread-1:23964][task_id:django.request][log.py:230][ERROR][Internal Server Error: /webmail/getmaillist/]
Traceback (most recent call last):
  File "D:\Anaconda3\envs\mail\lib\site-packages\django\core\handlers\exception.py", line 47, in inner
    response = get_response(request)
  File "D:\Anaconda3\envs\mail\lib\site-packages\django\core\handlers\base.py", line 181, in _get_response
    response = wrapped_callback(request, *callback_args, **callback_kwargs)
  File "D:\_2021Spring\计网\课设\DjangoMail\DjangoMail\WebMail\views.py", line 595, in GetAllMailsbyId
    "data": json.dumps(mailJsonList)
  File "D:\Anaconda3\envs\mail\lib\json\__init__.py", line 231, in dumps
    return _default_encoder.encode(obj)
  File "D:\Anaconda3\envs\mail\lib\json\encoder.py", line 199, in encode
    chunks = self.iterencode(o, _one_shot=True)
  File "D:\Anaconda3\envs\mail\lib\json\encoder.py", line 257, in iterencode
    return _iterencode(o, 0)
  File "D:\Anaconda3\envs\mail\lib\json\encoder.py", line 179, in default
    raise TypeError(f'Object of type {o.__class__.__name__} '
TypeError: Object of type date is not JSON serializable
[2021-05-16 21:31:36,513][Thread-2:11680][task_id:django.request][log.py:230][ERROR][Internal Server Error: /webmail/mails/1/]
Traceback (most recent call last):
  File "D:\Anaconda3\envs\mail\lib\site-packages\django\core\handlers\exception.py", line 47, in inner
    response = get_response(request)
  File "D:\Anaconda3\envs\mail\lib\site-packages\django\core\handlers\base.py", line 181, in _get_response
    response = wrapped_callback(request, *callback_args, **callback_kwargs)
  File "D:\Anaconda3\envs\mail\lib\site-packages\django\views\decorators\csrf.py", line 54, in wrapped_view
    return view_func(*args, **kwargs)
  File "D:\Anaconda3\envs\mail\lib\site-packages\rest_framework\viewsets.py", line 125, in view
    return self.dispatch(request, *args, **kwargs)
  File "D:\Anaconda3\envs\mail\lib\site-packages\rest_framework\views.py", line 509, in dispatch
    response = self.handle_exception(exc)
  File "D:\Anaconda3\envs\mail\lib\site-packages\rest_framework\views.py", line 469, in handle_exception
    self.raise_uncaught_exception(exc)
  File "D:\Anaconda3\envs\mail\lib\site-packages\rest_framework\views.py", line 480, in raise_uncaught_exception
    raise exc
  File "D:\Anaconda3\envs\mail\lib\site-packages\rest_framework\views.py", line 506, in dispatch
    response = handler(request, *args, **kwargs)
  File "D:\Anaconda3\envs\mail\lib\site-packages\rest_framework\mixins.py", line 82, in partial_update
    return self.update(request, *args, **kwargs)
  File "D:\Anaconda3\envs\mail\lib\site-packages\rest_framework\mixins.py", line 75, in update
    return Response(serializer.data)
  File "D:\Anaconda3\envs\mail\lib\site-packages\rest_framework\serializers.py", line 548, in data
    ret = super().data
  File "D:\Anaconda3\envs\mail\lib\site-packages\rest_framework\serializers.py", line 246, in data
    self._data = self.to_representation(self.instance)
  File "D:\Anaconda3\envs\mail\lib\site-packages\rest_framework\serializers.py", line 515, in to_representation
    ret[field.field_name] = field.to_representation(attribute)
  File "D:\Anaconda3\envs\mail\lib\site-packages\rest_framework\fields.py", line 1299, in to_representation
    'Expected a `date`, but got a `datetime`. Refusing to coerce, '
AssertionError: Expected a `date`, but got a `datetime`. Refusing to coerce, as this may mean losing timezone information. Use a custom read-only field and deal with timezone issues explicitly.
[2021-05-16 21:33:00,440][Thread-3:23172][task_id:django.request][log.py:230][ERROR][Internal Server Error: /webmail/mails/1/]
Traceback (most recent call last):
  File "D:\Anaconda3\envs\mail\lib\site-packages\django\core\handlers\exception.py", line 47, in inner
    response = get_response(request)
  File "D:\Anaconda3\envs\mail\lib\site-packages\django\core\handlers\base.py", line 181, in _get_response
    response = wrapped_callback(request, *callback_args, **callback_kwargs)
  File "D:\Anaconda3\envs\mail\lib\site-packages\django\views\decorators\csrf.py", line 54, in wrapped_view
    return view_func(*args, **kwargs)
  File "D:\Anaconda3\envs\mail\lib\site-packages\rest_framework\viewsets.py", line 125, in view
    return self.dispatch(request, *args, **kwargs)
  File "D:\Anaconda3\envs\mail\lib\site-packages\rest_framework\views.py", line 509, in dispatch
    response = self.handle_exception(exc)
  File "D:\Anaconda3\envs\mail\lib\site-packages\rest_framework\views.py", line 469, in handle_exception
    self.raise_uncaught_exception(exc)
  File "D:\Anaconda3\envs\mail\lib\site-packages\rest_framework\views.py", line 480, in raise_uncaught_exception
    raise exc
  File "D:\Anaconda3\envs\mail\lib\site-packages\rest_framework\views.py", line 506, in dispatch
    response = handler(request, *args, **kwargs)
  File "D:\Anaconda3\envs\mail\lib\site-packages\rest_framework\mixins.py", line 82, in partial_update
    return self.update(request, *args, **kwargs)
  File "D:\Anaconda3\envs\mail\lib\site-packages\rest_framework\mixins.py", line 75, in update
    return Response(serializer.data)
  File "D:\Anaconda3\envs\mail\lib\site-packages\rest_framework\serializers.py", line 548, in data
    ret = super().data
  File "D:\Anaconda3\envs\mail\lib\site-packages\rest_framework\serializers.py", line 246, in data
    self._data = self.to_representation(self.instance)
  File "D:\Anaconda3\envs\mail\lib\site-packages\rest_framework\serializers.py", line 515, in to_representation
    ret[field.field_name] = field.to_representation(attribute)
  File "D:\Anaconda3\envs\mail\lib\site-packages\rest_framework\fields.py", line 1299, in to_representation
    'Expected a `date`, but got a `datetime`. Refusing to coerce, '
AssertionError: Expected a `date`, but got a `datetime`. Refusing to coerce, as this may mean losing timezone information. Use a custom read-only field and deal with timezone issues explicitly.
